2024-01-17 06:25:26,584:DEBUG:certbot._internal.main:certbot version: 2.8.0
2024-01-17 06:25:26,584:DEBUG:certbot._internal.main:Location of certbot entry point: /usr/local/bin/certbot
2024-01-17 06:25:26,584:DEBUG:certbot._internal.main:Arguments: ['--webroot', '-w', '/var/www/certbot', '--email', 'tjfgkssk9472@gmail.com', '--agree-tos', '--no-eff-email', '-d', 'tairot.online']
2024-01-17 06:25:26,584:DEBUG:certbot._internal.main:Discovered plugins: PluginsRegistry(PluginEntryPoint#manual,PluginEntryPoint#null,PluginEntryPoint#standalone,PluginEntryPoint#webroot)
2024-01-17 06:25:26,915:DEBUG:certbot._internal.log:Root logging level set at 30
2024-01-17 06:25:26,921:DEBUG:certbot._internal.plugins.selection:Requested authenticator webroot and installer None
2024-01-17 06:25:26,922:DEBUG:certbot._internal.plugins.selection:Single candidate plugin: * webroot
Description: Saves the necessary validation files to a .well-known/acme-challenge/ directory within the nominated webroot path. A seperate HTTP server must be running and serving files from the webroot path. HTTP challenge only (wildcards not supported).
Interfaces: Authenticator, Plugin
Entry point: EntryPoint(name='webroot', value='certbot._internal.plugins.webroot:Authenticator', group='certbot.plugins')
Initialized: <certbot._internal.plugins.webroot.Authenticator object at 0x7f7718824a30>
Prep: True
2024-01-17 06:25:26,935:DEBUG:certbot._internal.plugins.selection:Selected authenticator <certbot._internal.plugins.webroot.Authenticator object at 0x7f7718824a30> and installer None
2024-01-17 06:25:26,937:INFO:certbot._internal.plugins.selection:Plugins selected: Authenticator webroot, Installer None
2024-01-17 06:25:27,029:DEBUG:certbot._internal.main:Picked account: <Account(RegistrationResource(body=Registration(key=None, contact=(), agreement=None, status=None, terms_of_service_agreed=None, only_return_existing=None, external_account_binding=None), uri='https://acme-v02.api.letsencrypt.org/acme/acct/1519022676', new_authzr_uri=None, terms_of_service=None), 053f50e92556dc2ae6fb1958ad04b4cb, Meta(creation_dt=datetime.datetime(2024, 1, 16, 8, 39, 49, tzinfo=<UTC>), creation_host='1b0b13fa81e7', register_to_eff=None))>
2024-01-17 06:25:27,030:DEBUG:acme.client:Sending GET request to https://acme-v02.api.letsencrypt.org/directory.
2024-01-17 06:25:27,034:DEBUG:urllib3.connectionpool:Starting new HTTPS connection (1): acme-v02.api.letsencrypt.org:443
2024-01-17 06:25:27,580:DEBUG:urllib3.connectionpool:https://acme-v02.api.letsencrypt.org:443 "GET /directory HTTP/1.1" 200 752
2024-01-17 06:25:27,582:DEBUG:acme.client:Received response:
HTTP 200
Server: nginx
Date: Wed, 17 Jan 2024 06:25:26 GMT
Content-Type: application/json
Content-Length: 752
Connection: keep-alive
Cache-Control: public, max-age=0, no-cache
X-Frame-Options: DENY
Strict-Transport-Security: max-age=604800

{
  "keyChange": "https://acme-v02.api.letsencrypt.org/acme/key-change",
  "meta": {
    "caaIdentities": [
      "letsencrypt.org"
    ],
    "termsOfService": "https://letsencrypt.org/documents/LE-SA-v1.3-September-21-2022.pdf",
    "website": "https://letsencrypt.org"
  },
  "newAccount": "https://acme-v02.api.letsencrypt.org/acme/new-acct",
  "newNonce": "https://acme-v02.api.letsencrypt.org/acme/new-nonce",
  "newOrder": "https://acme-v02.api.letsencrypt.org/acme/new-order",
  "pm5nMPK_2Ns": "https://community.letsencrypt.org/t/adding-random-entries-to-the-directory/33417",
  "renewalInfo": "https://acme-v02.api.letsencrypt.org/draft-ietf-acme-ari-02/renewalInfo/",
  "revokeCert": "https://acme-v02.api.letsencrypt.org/acme/revoke-cert"
}
2024-01-17 06:25:27,585:DEBUG:certbot._internal.display.obj:Notifying user: Requesting a certificate for tairot.online
2024-01-17 06:25:27,589:DEBUG:acme.client:Requesting fresh nonce
2024-01-17 06:25:27,589:DEBUG:acme.client:Sending HEAD request to https://acme-v02.api.letsencrypt.org/acme/new-nonce.
2024-01-17 06:25:27,757:DEBUG:urllib3.connectionpool:https://acme-v02.api.letsencrypt.org:443 "HEAD /acme/new-nonce HTTP/1.1" 200 0
2024-01-17 06:25:27,759:DEBUG:acme.client:Received response:
HTTP 200
Server: nginx
Date: Wed, 17 Jan 2024 06:25:27 GMT
Connection: keep-alive
Cache-Control: public, max-age=0, no-cache
Link: <https://acme-v02.api.letsencrypt.org/directory>;rel="index"
Replay-Nonce: cBLV7b5iG-l6idAlxuBavrIMNMZYiZL20RRM8zGRYiBAEzAu9hw
X-Frame-Options: DENY
Strict-Transport-Security: max-age=604800


2024-01-17 06:25:27,760:DEBUG:acme.client:Storing nonce: cBLV7b5iG-l6idAlxuBavrIMNMZYiZL20RRM8zGRYiBAEzAu9hw
2024-01-17 06:25:27,761:DEBUG:acme.client:JWS payload:
b'{\n  "identifiers": [\n    {\n      "type": "dns",\n      "value": "tairot.online"\n    }\n  ]\n}'
2024-01-17 06:25:27,765:DEBUG:acme.client:Sending POST request to https://acme-v02.api.letsencrypt.org/acme/new-order:
{
  "protected": "eyJhbGciOiAiUlMyNTYiLCAia2lkIjogImh0dHBzOi8vYWNtZS12MDIuYXBpLmxldHNlbmNyeXB0Lm9yZy9hY21lL2FjY3QvMTUxOTAyMjY3NiIsICJub25jZSI6ICJjQkxWN2I1aUctbDZpZEFseHVCYXZySU1OTVpZaVpMMjBSUk04ekdSWWlCQUV6QXU5aHciLCAidXJsIjogImh0dHBzOi8vYWNtZS12MDIuYXBpLmxldHNlbmNyeXB0Lm9yZy9hY21lL25ldy1vcmRlciJ9",
  "signature": "jM9WqBqOhSwSkE2GS4cNR5lB5VkqSHOGu-gCwaUZcEYdJz2mOGvYHIr2ME1s0R1sBfR6uswinEZagafmZ99v1uu8pHZ1p00L8GHT80gpeEqGQQmM5OC8kkMmXEU8cvntpRVGLpdAkYP93kQK6jWC7yBUUjZQ0qpnOoibVJbDr-DE_bN0ByoMuJMuOmB9wScY-CoGPbZQkw40o-CeZQZ0s2SYDmKzpXV_O3wawOHKc6lloA604LsS5bbHcapOgslTE9V6R-TrFDc-IRmpFp7wgV0LjeeYL88rbyg3JevJhitxczt4wI2RYloiOq9qxjtl0VIgwjSDHy1ae-7D3YyUfA",
  "payload": "ewogICJpZGVudGlmaWVycyI6IFsKICAgIHsKICAgICAgInR5cGUiOiAiZG5zIiwKICAgICAgInZhbHVlIjogInRhaXJvdC5vbmxpbmUiCiAgICB9CiAgXQp9"
}
2024-01-17 06:25:27,975:DEBUG:urllib3.connectionpool:https://acme-v02.api.letsencrypt.org:443 "POST /acme/new-order HTTP/1.1" 429 213
2024-01-17 06:25:27,977:DEBUG:acme.client:Received response:
HTTP 429
Server: nginx
Date: Wed, 17 Jan 2024 06:25:27 GMT
Content-Type: application/problem+json
Content-Length: 213
Connection: keep-alive
Boulder-Requester: 1519022676
Cache-Control: public, max-age=0, no-cache
Link: <https://acme-v02.api.letsencrypt.org/directory>;rel="index"
Replay-Nonce: cBLV7b5iz-cMI0cKU4tzPyRrZhRV4lDYylLf8UX1D1Si90WufFo

{
  "type": "urn:ietf:params:acme:error:rateLimited",
  "detail": "Error creating new order :: too many failed authorizations recently: see https://letsencrypt.org/docs/failed-validation-limit/",
  "status": 429
}
2024-01-17 06:25:27,979:DEBUG:certbot._internal.log:Exiting abnormally:
Traceback (most recent call last):
  File "/usr/local/bin/certbot", line 33, in <module>
    sys.exit(load_entry_point('certbot', 'console_scripts', 'certbot')())
  File "/opt/certbot/src/certbot/certbot/main.py", line 19, in main
    return internal_main.main(cli_args)
  File "/opt/certbot/src/certbot/certbot/_internal/main.py", line 1869, in main
    return config.func(config, plugins)
  File "/opt/certbot/src/certbot/certbot/_internal/main.py", line 1600, in certonly
    lineage = _get_and_save_cert(le_client, config, domains, certname, lineage)
  File "/opt/certbot/src/certbot/certbot/_internal/main.py", line 143, in _get_and_save_cert
    lineage = le_client.obtain_and_enroll_certificate(domains, certname)
  File "/opt/certbot/src/certbot/certbot/_internal/client.py", line 517, in obtain_and_enroll_certificate
    cert, chain, key, _ = self.obtain_certificate(domains)
  File "/opt/certbot/src/certbot/certbot/_internal/client.py", line 428, in obtain_certificate
    orderr = self._get_order_and_authorizations(csr.data, self.config.allow_subset_of_names)
  File "/opt/certbot/src/certbot/certbot/_internal/client.py", line 478, in _get_order_and_authorizations
    orderr = self.acme.new_order(csr_pem)
  File "/opt/certbot/src/acme/acme/client.py", line 137, in new_order
    response = self._post(self.directory['newOrder'], order)
  File "/opt/certbot/src/acme/acme/client.py", line 365, in _post
    return self.net.post(*args, **kwargs)
  File "/opt/certbot/src/acme/acme/client.py", line 738, in post
    return self._post_once(*args, **kwargs)
  File "/opt/certbot/src/acme/acme/client.py", line 751, in _post_once
    response = self._check_response(response, content_type=content_type)
  File "/opt/certbot/src/acme/acme/client.py", line 602, in _check_response
    raise messages.Error.from_json(jobj)
acme.messages.Error: urn:ietf:params:acme:error:rateLimited :: There were too many requests of a given type :: Error creating new order :: too many failed authorizations recently: see https://letsencrypt.org/docs/failed-validation-limit/
2024-01-17 06:25:27,984:ERROR:certbot._internal.log:An unexpected error occurred:
2024-01-17 06:25:27,985:ERROR:certbot._internal.log:Error creating new order :: too many failed authorizations recently: see https://letsencrypt.org/docs/failed-validation-limit/
